File: U_files/LabAvII/DRX/La2O3.csv
[Measurement conditions]
Sample identification,La2O3
Comment - 1,"Configuration=Plataforma Reflexion-Transmision spinner, Owner=User-1, Creation date=2/3/2023 7:20:03 AM"
Comment - 2,"Goniometer=Omega/2Theta; Minimum step size 2Theta:0.0001; Minimum step size Omega:0.0001"
Comment - 3,"Sample stage=Reflection-transmission spinner; Minimum step size Phi:0.1"
Comment - 4,"Diffractometer system=EMPYREAN"
Comment - 5,"Measurement program=C:\PANalytical\Data Collector\Programs\DRX01-005-5-80.xrdmp, Identifier={D2D94ECF-D8E1-4D65-A9F1-1EA3648327E6}"
Comment - 6,"Batch program=C:\PANalytical\Data Collector\Programs\BATCH.xrdmp, Identifier={1A5E0411-49C0-46C9-A459-383431844E05}"
Anode material,Cu
K-Alpha1 wavelength,1.5405980
K-Alpha2 wavelength,1.5444260
Ratio K-Alpha2/K-Alpha1,0.500
Divergence slit,Fixed,0.5
Monochromator used,NO
Generator voltage, 45
Tube current, 40
File date and time,07/Mar/2023 14:03
Unit cell,
h k l, 0 0 0
Scan axis,Gonio
Scan range,4.999799996,79.999969724
Scan step size,0.0525211
No. of points, 1428
Scan type,CONTINUOUS
Phi,172.6
Time per step,44.880
[Scan points]
Angle,Intensity
5.026060560,4678.0
5.078581687,4658.0
5.131102815,4542.0
5.183623942,4538.0
5.236145069,4412.0
5.288666196,4410.0
5.341187324,4395.0
5.393708451,4372.0
5.446229578,4147.0
5.498750705,4132.0
5.551271833,4279.0
5.603792960,4075.0
5.656314087,4075.0
5.708835214,4022.0
5.761356342,3984.0
5.813877469,3925.0
5.866398596,4098.0
5.918919723,3964.0
5.971440851,3980.0
6.023961978,4010.0
6.076483105,4029.0
6.129004232,3943.0
6.181525360,3958.0
6.234046487,3973.0
6.286567614,3922.0
6.339088741,3882.0
6.391609869,3935.0
6.444130996,3945.0
6.496652123,3978.0
6.549173251,3918.0
6.601694378,3903.0
6.654215505,3919.0
6.706736632,3893.0
6.759257760,3918.0
6.811778887,3869.0
6.864300014,3823.0
6.916821141,3904.0
6.969342269,3888.0
7.021863396,3732.0
7.074384523,3877.0
7.126905650,3792.0
7.179426778,3841.0
7.231947905,3785.0
7.284469032,3832.0
7.336990159,3790.0
7.389511287,3761.0
7.442032414,3771.0
7.494553541,3812.0
7.547074668,3796.0
7.599595796,3665.0
7.652116923,3726.0
7.704638050,3783.0
7.757159178,3722.0
7.809680305,3618.0
7.862201432,3722.0
7.914722559,3785.0
7.967243687,3766.0
8.019764814,3669.0
8.072285941,3750.0
8.124807068,3691.0
8.177328196,3690.0
8.229849323,3633.0
8.282370450,3638.0
8.334891577,3594.0
8.387412705,3611.0
8.439933832,3634.0
8.492454959,3649.0
8.544976086,3648.0
8.597497214,3453.0
8.650018341,3612.0
8.702539468,3554.0
8.755060595,3565.0
8.807581723,3607.0
8.860102850,3537.0
8.912623977,3423.0
8.965145104,3641.0
9.017666232,3510.0
9.070187359,3517.0
9.122708486,3464.0
9.175229614,3378.0
9.227750741,3427.0
9.280271868,3440.0
9.332792995,3405.0
9.385314123,3310.0
9.437835250,3314.0
9.490356377,3515.0
9.542877504,3336.0
9.595398632,3392.0
9.647919759,3356.0
9.700440886,3381.0
9.752962013,3339.0
9.805483141,3307.0
9.858004268,3336.0
9.910525395,3216.0
9.963046522,3298.0
10.015567650,3275.0
10.068088777,3097.0
10.120609904,3214.0
10.173131031,3214.0
10.225652159,3189.0
10.278173286,3208.0
10.330694413,3152.0
10.383215541,3151.0
10.435736668,3062.0
10.488257795,3120.0
10.540778922,3084.0
10.593300050,3083.0
10.645821177,2930.0
10.698342304,3050.0
10.750863431,3129.0
10.803384559,3149.0
10.855905686,3127.0
10.908426813,3042.0
10.960947940,2953.0
11.013469068,2884.0
11.065990195,2888.0
11.118511322,2969.0
11.171032449,2903.0
11.223553577,2891.0
11.276074704,2872.0
11.328595831,2801.0
11.381116958,2919.0
11.433638086,2838.0
11.486159213,2872.0
11.538680340,2793.0
11.591201467,2691.0
11.643722595,2720.0
11.696243722,2766.0
11.748764849,2809.0
11.801285977,2735.0
11.853807104,2723.0
11.906328231,2714.0
11.958849358,2653.0
12.011370486,2678.0
12.063891613,2720.0
12.116412740,2680.0
12.168933867,2544.0
12.221454995,2570.0
12.273976122,2658.0
12.326497249,2743.0
12.379018376,2621.0
12.431539504,2546.0
12.484060631,2518.0
12.536581758,2584.0
12.589102885,2535.0
12.641624013,2510.0
12.694145140,2504.0
12.746666267,2428.0
12.799187394,2500.0
12.851708522,2504.0
12.904229649,2475.0
12.956750776,2402.0
13.009271904,2509.0
13.061793031,2455.0
13.114314158,2432.0
13.166835285,2374.0
13.219356413,2375.0
13.271877540,2400.0
13.324398667,2329.0
13.376919794,2257.0
13.429440922,2456.0
13.481962049,2363.0
13.534483176,2252.0
13.587004303,2313.0
13.639525431,2344.0
13.692046558,2294.0
13.744567685,2367.0
13.797088812,2272.0
13.849609940,2316.0
13.902131067,2310.0
13.954652194,2243.0
14.007173321,2159.0
14.059694449,2204.0
14.112215576,2300.0
14.164736703,2290.0
14.217257830,2203.0
14.269778958,2196.0
14.322300085,2206.0
14.374821212,2104.0
14.427342340,2145.0
14.479863467,2189.0
14.532384594,2187.0
14.584905721,2155.0
14.637426849,2153.0
14.689947976,2145.0
14.742469103,2162.0
14.794990230,2149.0
14.847511358,2111.0
14.900032485,2160.0
14.952553612,2158.0
15.005074739,2100.0
15.057595867,2157.0
15.110116994,2151.0
15.162638121,2222.0
15.215159248,2386.0
15.267680376,2456.0
15.320201503,2621.0
15.372722630,2827.0
15.425243757,3230.0
15.477764885,3871.0
15.530286012,4912.0
15.582807139,6365.0
15.635328267,8165.0
15.687849394,8888.0
15.740370521,7028.0
15.792891648,4799.0
15.845412776,3475.0
15.897933903,2845.0
15.950455030,2416.0
16.002976157,2242.0
16.055497285,2105.0
16.108018412,1995.0
16.160539539,1956.0
16.213060666,1942.0
16.265581794,1930.0
16.318102921,1875.0
16.370624048,1756.0
16.423145175,1797.0
16.475666303,1784.0
16.528187430,1797.0
16.580708557,1784.0
16.633229684,1674.0
16.685750812,1696.0
16.738271939,1798.0
16.790793066,1680.0
16.843314193,1664.0
16.895835321,1662.0
16.948356448,1589.0
17.000877575,1660.0
17.053398703,1626.0
17.105919830,1625.0
17.158440957,1620.0
17.210962084,1645.0
17.263483212,1652.0
17.316004339,1595.0
17.368525466,1565.0
17.421046593,1535.0
17.473567721,1501.0
17.526088848,1595.0
17.578609975,1564.0
17.631131102,1652.0
17.683652230,1597.0
17.736173357,1594.0
17.788694484,1587.0
17.841215611,1613.0
17.893736739,1517.0
17.946257866,1590.0
17.998778993,1516.0
18.051300120,1440.0
18.103821248,1585.0
18.156342375,1488.0
18.208863502,1519.0
18.261384630,1455.0
18.313905757,1476.0
18.366426884,1432.0
18.418948011,1411.0
18.471469139,1424.0
18.523990266,1498.0
18.576511393,1432.0
18.629032520,1434.0
18.681553648,1375.0
18.734074775,1379.0
18.786595902,1370.0
18.839117029,1396.0
18.891638157,1317.0
18.944159284,1377.0
18.996680411,1401.0
19.049201538,1356.0
19.101722666,1383.0
19.154243793,1380.0
19.206764920,1386.0
19.259286047,1396.0
19.311807175,1341.0
19.364328302,1335.0
19.416849429,1358.0
19.469370556,1450.0
19.521891684,1407.0
19.574412811,1329.0
19.626933938,1305.0
19.679455066,1285.0
19.731976193,1362.0
19.784497320,1318.0
19.837018447,1339.0
19.889539575,1294.0
19.942060702,1297.0
19.994581829,1294.0
20.047102956,1264.0
20.099624084,1243.0
20.152145211,1219.0
20.204666338,1301.0
20.257187465,1204.0
20.309708593,1224.0
20.362229720,1284.0
20.414750847,1232.0
20.467271974,1136.0
20.519793102,1193.0
20.572314229,1245.0
20.624835356,1215.0
20.677356483,1243.0
20.729877611,1209.0
20.782398738,1236.0
20.834919865,1223.0
20.887440993,1190.0
20.939962120,1224.0
20.992483247,1155.0
21.045004374,1171.0
21.097525502,1118.0
21.150046629,1227.0
21.202567756,1151.0
21.255088883,1149.0
21.307610011,1264.0
21.360131138,1165.0
21.412652265,1142.0
21.465173392,1136.0
21.517694520,1171.0
21.570215647,1102.0
21.622736774,1139.0
21.675257901,1183.0
21.727779029,1184.0
21.780300156,1081.0
21.832821283,1180.0
21.885342410,1102.0
21.937863538,1068.0
21.990384665,1058.0
22.042905792,1159.0
22.095426919,1075.0
22.147948047,1058.0
22.200469174,1095.0
22.252990301,1186.0
22.305511429,1201.0
22.358032556,1136.0
22.410553683,1093.0
22.463074810,1037.0
22.515595938,1043.0
22.568117065,1063.0
22.620638192,1085.0
22.673159319,1078.0
22.725680447,1116.0
22.778201574,1085.0
22.830722701,1037.0
22.883243828,1083.0
22.935764956,1076.0
22.988286083,1056.0
23.040807210,1016.0
23.093328337,1064.0
23.145849465,1020.0
23.198370592,1062.0
23.250891719,1014.0
23.303412846,1053.0
23.355933974,1023.0
23.408455101,977.0
23.460976228,1027.0
23.513497356,1028.0
23.566018483,1014.0
23.618539610,1019.0
23.671060737,998.0
23.723581865,967.0
23.776102992,995.0
23.828624119,996.0
23.881145246,988.0
23.933666374,1009.0
23.986187501,1039.0
24.038708628,1022.0
24.091229755,968.0
24.143750883,947.0
24.196272010,989.0
24.248793137,1035.0
24.301314264,1116.0
24.353835392,1135.0
24.406356519,1156.0
24.458877646,1174.0
24.511398773,1022.0
24.563919901,1069.0
24.616441028,1032.0
24.668962155,1008.0
24.721483282,989.0
24.774004410,920.0
24.826525537,917.0
24.879046664,939.0
24.931567792,943.0
24.984088919,896.0
25.036610046,989.0
25.089131173,946.0
25.141652301,975.0
25.194173428,1002.0
25.246694555,963.0
25.299215682,965.0
25.351736810,930.0
25.404257937,963.0
25.456779064,915.0
25.509300191,926.0
25.561821319,862.0
25.614342446,914.0
25.666863573,907.0
25.719384700,913.0
25.771905828,923.0
25.824426955,1003.0
25.876948082,973.0
25.929469209,959.0
25.981990337,864.0
26.034511464,877.0
26.087032591,926.0
26.139553719,921.0
26.192074846,842.0
26.244595973,928.0
26.297117100,959.0
26.349638228,930.0
26.402159355,905.0
26.454680482,957.0
26.507201609,935.0
26.559722737,906.0
26.612243864,1023.0
26.664764991,974.0
26.717286118,1036.0
26.769807246,1029.0
26.822328373,1047.0
26.874849500,1149.0
26.927370627,1241.0
26.979891755,1464.0
27.032412882,1668.0
27.084934009,2001.0
27.137455136,2545.0
27.189976264,3533.0
27.242497391,4625.0
27.295018518,5589.0
27.347539645,5691.0
27.400060773,4851.0
27.452581900,3751.0
27.505103027,2807.0
27.557624155,2319.0
27.610145282,2053.0
27.662666409,2084.0
27.715187536,2338.0
27.767708664,2679.0
27.820229791,3706.0
27.872750918,5034.0
27.925272045,6933.0
27.977793173,8362.0
28.030314300,8016.0
28.082835427,6304.0
28.135356554,4467.0
28.187877682,2990.0
28.240398809,2137.0
28.292919936,1615.0
28.345441063,1337.0
28.397962191,1269.0
28.450483318,1106.0
28.503004445,1046.0
28.555525572,989.0
28.608046700,948.0
28.660567827,932.0
28.713088954,818.0
28.765610082,893.0
28.818131209,872.0
28.870652336,801.0
28.923173463,828.0
28.975694591,790.0
29.028215718,817.0
29.080736845,790.0
29.133257972,818.0
29.185779100,780.0
29.238300227,783.0
29.290821354,770.0
29.343342481,800.0
29.395863609,801.0
29.448384736,734.0
29.500905863,797.0
29.553426990,812.0
29.605948118,728.0
29.658469245,703.0
29.710990372,652.0
29.763511499,738.0
29.816032627,773.0
29.868553754,749.0
29.921074881,749.0
29.973596008,775.0
30.026117136,719.0
30.078638263,795.0
30.131159390,768.0
30.183680518,892.0
30.236201645,835.0
30.288722772,964.0
30.341243899,971.0
30.393765027,1016.0
30.446286154,878.0
30.498807281,828.0
30.551328408,768.0
30.603849536,810.0
30.656370663,725.0
30.708891790,668.0
30.761412917,735.0
30.813934045,720.0
30.866455172,715.0
30.918976299,712.0
30.971497426,733.0
31.024018554,691.0
31.076539681,745.0
31.129060808,727.0
31.181581935,710.0
31.234103063,750.0
31.286624190,787.0
31.339145317,823.0
31.391666445,951.0
31.444187572,1040.0
31.496708699,1205.0
31.549229826,1332.0
31.601750954,1590.0
31.654272081,1701.0
31.706793208,1600.0
31.759314335,1336.0
31.811835463,1140.0
31.864356590,960.0
31.916877717,795.0
31.969398844,825.0
32.021919972,758.0
32.074441099,702.0
32.126962226,715.0
32.179483353,660.0
32.232004481,625.0
32.284525608,672.0
32.337046735,598.0
32.389567862,654.0
32.442088990,638.0
32.494610117,621.0
32.547131244,676.0
32.599652371,639.0
32.652173499,609.0
32.704694626,605.0
32.757215753,641.0
32.809736881,658.0
32.862258008,625.0
32.914779135,627.0
32.967300262,595.0
33.019821390,587.0
33.072342517,617.0
33.124863644,599.0
33.177384771,634.0
33.229905899,625.0
33.282427026,601.0
33.334948153,597.0
33.387469280,657.0
33.439990408,601.0
33.492511535,606.0
33.545032662,645.0
33.597553789,562.0
33.650074917,618.0
33.702596044,622.0
33.755117171,606.0
33.807638298,591.0
33.860159426,577.0
33.912680553,599.0
33.965201680,609.0
34.017722808,558.0
34.070243935,565.0
34.122765062,561.0
34.175286189,539.0
34.227807317,597.0
34.280328444,566.0
34.332849571,553.0
34.385370698,528.0
34.437891826,581.0
34.490412953,559.0
34.542934080,589.0
34.595455207,558.0
34.647976335,594.0
34.700497462,532.0
34.753018589,551.0
34.805539716,530.0
34.858060844,577.0
34.910581971,545.0
34.963103098,524.0
35.015624225,543.0
35.068145353,545.0
35.120666480,540.0
35.173187607,548.0
35.225708734,553.0
35.278229862,567.0
35.330750989,532.0
35.383272116,538.0
35.435793244,559.0
35.488314371,580.0
35.540835498,529.0
35.593356625,532.0
35.645877753,535.0
35.698398880,616.0
35.750920007,672.0
35.803441134,662.0
35.855962262,730.0
35.908483389,793.0
35.961004516,903.0
36.013525643,993.0
36.066046771,935.0
36.118567898,878.0
36.171089025,789.0
36.223610152,684.0
36.276131280,632.0
36.328652407,602.0
36.381173534,515.0
36.433694661,532.0
36.486215789,513.0
36.538736916,562.0
36.591258043,545.0
36.643779171,571.0
36.696300298,530.0
36.748821425,561.0
36.801342552,532.0
36.853863680,518.0
36.906384807,511.0
36.958905934,505.0
37.011427061,540.0
37.063948189,483.0
37.116469316,525.0
37.168990443,458.0
37.221511570,496.0
37.274032698,512.0
37.326553825,476.0
37.379074952,495.0
37.431596079,473.0
37.484117207,480.0
37.536638334,492.0
37.589159461,511.0
37.641680588,469.0
37.694201716,473.0
37.746722843,484.0
37.799243970,525.0
37.851765097,539.0
37.904286225,498.0
37.956807352,478.0
38.009328479,499.0
38.061849607,524.0
38.114370734,473.0
38.166891861,494.0
38.219412988,518.0
38.271934116,519.0
38.324455243,529.0
38.376976370,540.0
38.429497497,592.0
38.482018625,536.0
38.534539752,508.0
38.587060879,516.0
38.639582006,563.0
38.692103134,555.0
38.744624261,545.0
38.797145388,526.0
38.849666515,545.0
38.902187643,600.0
38.954708770,690.0
39.007229897,738.0
39.059751024,756.0
39.112272152,880.0
39.164793279,1092.0
39.217314406,1265.0
39.269835534,1682.0
39.322356661,2249.0
39.374877788,2908.0
39.427398915,3742.0
39.479920043,4593.0
39.532441170,4725.0
39.584962297,4184.0
39.637483424,3538.0
39.690004552,2727.0
39.742525679,2015.0
39.795046806,1549.0
39.847567933,1242.0
39.900089061,1017.0
39.952610188,823.0
40.005131315,727.0
40.057652442,749.0
40.110173570,675.0
40.162694697,626.0
40.215215824,619.0
40.267736951,556.0
40.320258079,542.0
40.372779206,468.0
40.425300333,536.0
40.477821460,501.0
40.530342588,505.0
40.582863715,502.0
40.635384842,519.0
40.687905970,508.0
40.740427097,479.0
40.792948224,459.0
40.845469351,453.0
40.897990479,519.0
40.950511606,485.0
41.003032733,472.0
41.055553860,466.0
41.108074988,453.0
41.160596115,466.0
41.213117242,499.0
41.265638369,439.0
41.318159497,454.0
41.370680624,450.0
41.423201751,454.0
41.475722878,452.0
41.528244006,463.0
41.580765133,474.0
41.633286260,493.0
41.685807387,442.0
41.738328515,474.0
41.790849642,478.0
41.843370769,486.0
41.895891897,525.0
41.948413024,585.0
42.000934151,575.0
42.053455278,628.0
42.105976406,674.0
42.158497533,846.0
42.211018660,1034.0
42.263539787,974.0
42.316060915,1027.0
42.368582042,990.0
42.421103169,951.0
42.473624296,817.0
42.526145424,735.0
42.578666551,649.0
42.631187678,651.0
42.683708805,537.0
42.736229933,551.0
42.788751060,488.0
42.841272187,546.0
42.893793314,544.0
42.946314442,535.0
42.998835569,521.0
43.051356696,458.0
43.103877823,449.0
43.156398951,455.0
43.208920078,464.0
43.261441205,432.0
43.313962333,449.0
43.366483460,462.0
43.419004587,459.0
43.471525714,463.0
43.524046842,450.0
43.576567969,461.0
43.629089096,465.0
43.681610223,485.0
43.734131351,469.0
43.786652478,496.0
43.839173605,512.0
43.891694732,505.0
43.944215860,475.0
43.996736987,447.0
44.049258114,435.0
44.101779241,484.0
44.154300369,398.0
44.206821496,443.0
44.259342623,408.0
44.311863750,463.0
44.364384878,443.0
44.416906005,466.0
44.469427132,419.0
44.521948260,428.0
44.574469387,398.0
44.626990514,406.0
44.679511641,405.0
44.732032769,433.0
44.784553896,385.0
44.837075023,372.0
44.889596150,403.0
44.942117278,405.0
44.994638405,419.0
45.047159532,404.0
45.099680659,401.0
45.152201787,408.0
45.204722914,407.0
45.257244041,410.0
45.309765168,392.0
45.362286296,384.0
45.414807423,374.0
45.467328550,409.0
45.519849677,410.0
45.572370805,390.0
45.624891932,366.0
45.677413059,398.0
45.729934186,351.0
45.782455314,387.0
45.834976441,363.0
45.887497568,401.0
45.940018696,386.0
45.992539823,404.0
46.045060950,397.0
46.097582077,382.0
46.150103205,414.0
46.202624332,392.0
46.255145459,411.0
46.307666586,426.0
46.360187714,413.0
46.412708841,435.0
46.465229968,426.0
46.517751095,413.0
46.570272223,434.0
46.622793350,451.0
46.675314477,481.0
46.727835604,495.0
46.780356732,586.0
46.832877859,621.0
46.885398986,721.0
46.937920113,853.0
46.990441241,1006.0
47.042962368,1068.0
47.095483495,1179.0
47.148004623,1156.0
47.200525750,1049.0
47.253046877,874.0
47.305568004,760.0
47.358089132,675.0
47.410610259,625.0
47.463131386,604.0
47.515652513,568.0
47.568173641,568.0
47.620694768,544.0
47.673215895,553.0
47.725737022,527.0
47.778258150,586.0
47.830779277,649.0
47.883300404,704.0
47.935821531,746.0
47.988342659,840.0
48.040863786,1002.0
48.093384913,1176.0
48.145906040,1455.0
48.198427168,1756.0
48.250948295,1899.0
48.303469422,2191.0
48.355990549,2120.0
48.408511677,2263.0
48.461032804,2313.0
48.513553931,2495.0
48.566075059,2984.0
48.618596186,3366.0
48.671117313,3479.0
48.723638440,3501.0
48.776159568,3373.0
48.828680695,2862.0
48.881201822,2279.0
48.933722949,1857.0
48.986244077,1474.0
49.038765204,1202.0
49.091286331,985.0
49.143807458,861.0
49.196328586,742.0
49.248849713,677.0
49.301370840,613.0
49.353891967,563.0
49.406413095,557.0
49.458934222,536.0
49.511455349,568.0
49.563976476,530.0
49.616497604,497.0
49.669018731,564.0
49.721539858,646.0
49.774060986,657.0
49.826582113,731.0
49.879103240,855.0
49.931624367,910.0
49.984145495,879.0
50.036666622,735.0
50.089187749,651.0
50.141708876,614.0
50.194230004,592.0
50.246751131,502.0
50.299272258,454.0
50.351793385,424.0
50.404314513,392.0
50.456835640,456.0
50.509356767,404.0
50.561877894,385.0
50.614399022,362.0
50.666920149,362.0
50.719441276,400.0
50.771962403,358.0
50.824483531,337.0
50.877004658,341.0
50.929525785,383.0
50.982046912,352.0
51.034568040,375.0
51.087089167,365.0
51.139610294,353.0
51.192131422,359.0
51.244652549,315.0
51.297173676,349.0
51.349694803,387.0
51.402215931,328.0
51.454737058,355.0
51.507258185,300.0
51.559779312,329.0
51.612300440,341.0
51.664821567,335.0
51.717342694,314.0
51.769863821,339.0
51.822384949,326.0
51.874906076,351.0
51.927427203,315.0
51.979948330,328.0
52.032469458,336.0
52.084990585,340.0
52.137511712,368.0
52.190032839,323.0
52.242553967,348.0
52.295075094,317.0
52.347596221,318.0
52.400117349,301.0
52.452638476,303.0
52.505159603,330.0
52.557680730,316.0
52.610201858,309.0
52.662722985,342.0
52.715244112,318.0
52.767765239,334.0
52.820286367,326.0
52.872807494,317.0
52.925328621,303.0
52.977849748,326.0
53.030370876,367.0
53.082892003,311.0
53.135413130,295.0
53.187934257,346.0
53.240455385,359.0
53.292976512,358.0
53.345497639,309.0
53.398018766,362.0
53.450539894,351.0
53.503061021,348.0
53.555582148,302.0
53.608103275,337.0
53.660624403,334.0
53.713145530,327.0
53.765666657,291.0
53.818187785,332.0
53.870708912,321.0
53.923230039,274.0
53.975751166,292.0
54.028272294,304.0
54.080793421,345.0
54.133314548,307.0
54.185835675,269.0
54.238356803,343.0
54.290877930,315.0
54.343399057,315.0
54.395920184,338.0
54.448441312,291.0
54.500962439,325.0
54.553483566,350.0
54.606004693,345.0
54.658525821,362.0
54.711046948,391.0
54.763568075,405.0
54.816089202,433.0
54.868610330,418.0
54.921131457,489.0
54.973652584,537.0
55.026173712,633.0
55.078694839,690.0
55.131215966,876.0
55.183737093,978.0
55.236258221,1185.0
55.288779348,1279.0
55.341300475,1216.0
55.393821602,1093.0
55.446342730,1024.0
55.498863857,910.0
55.551384984,730.0
55.603906111,617.0
55.656427239,531.0
55.708948366,493.0
55.761469493,482.0
55.813990620,451.0
55.866511748,419.0
55.919032875,406.0
55.971554002,400.0
56.024075129,476.0
56.076596257,432.0
56.129117384,503.0
56.181638511,544.0
56.234159638,630.0
56.286680766,656.0
56.339201893,654.0
56.391723020,708.0
56.444244148,653.0
56.496765275,634.0
56.549286402,596.0
56.601807529,537.0
56.654328657,498.0
56.706849784,477.0
56.759370911,415.0
56.811892038,366.0
56.864413166,380.0
56.916934293,398.0
56.969455420,359.0
57.021976547,343.0
57.074497675,349.0
57.127018802,347.0
57.179539929,388.0
57.232061056,381.0
57.284582184,358.0
57.337103311,330.0
57.389624438,347.0
57.442145565,372.0
57.494666693,377.0
57.547187820,350.0
57.599708947,385.0
57.652230075,398.0
57.704751202,401.0
57.757272329,482.0
57.809793456,533.0
57.862314584,489.0
57.914835711,512.0
57.967356838,490.0
58.019877965,443.0
58.072399093,402.0
58.124920220,354.0
58.177441347,385.0
58.229962474,363.0
58.282483602,367.0
58.335004729,339.0
58.387525856,313.0
58.440046983,301.0
58.492568111,334.0
58.545089238,378.0
58.597610365,362.0
58.650131492,393.0
58.702652620,437.0
58.755173747,430.0
58.807694874,453.0
58.860216001,467.0
58.912737129,490.0
58.965258256,443.0
59.017779383,447.0
59.070300511,409.0
59.122821638,402.0
59.175342765,353.0
59.227863892,341.0
59.280385020,364.0
59.332906147,292.0
59.385427274,285.0
59.437948401,270.0
59.490469529,280.0
59.542990656,284.0
59.595511783,273.0
59.648032910,263.0
59.700554038,286.0
59.753075165,243.0
59.805596292,277.0
59.858117419,310.0
59.910638547,252.0
59.963159674,272.0
60.015680801,269.0
60.068201928,262.0
60.120723056,275.0
60.173244183,233.0
60.225765310,250.0
60.278286438,236.0
60.330807565,233.0
60.383328692,254.0
60.435849819,261.0
60.488370947,250.0
60.540892074,257.0
60.593413201,299.0
60.645934328,257.0
60.698455456,258.0
60.750976583,278.0
60.803497710,235.0
60.856018837,272.0
60.908539965,238.0
60.961061092,302.0
61.013582219,261.0
61.066103346,241.0
61.118624474,289.0
61.171145601,264.0
61.223666728,248.0
61.276187855,267.0
61.328708983,277.0
61.381230110,261.0
61.433751237,270.0
61.486272364,288.0
61.538793492,252.0
61.591314619,232.0
61.643835746,259.0
61.696356874,291.0
61.748878001,239.0
61.801399128,271.0
61.853920255,296.0
61.906441383,233.0
61.958962510,261.0
62.011483637,251.0
62.064004764,285.0
62.116525892,257.0
62.169047019,268.0
62.221568146,269.0
62.274089273,268.0
62.326610401,277.0
62.379131528,248.0
62.431652655,256.0
62.484173782,267.0
62.536694910,267.0
62.589216037,272.0
62.641737164,269.0
62.694258291,289.0
62.746779419,260.0
62.799300546,257.0
62.851821673,295.0
62.904342801,278.0
62.956863928,276.0
63.009385055,260.0
63.061906182,310.0
63.114427310,280.0
63.166948437,277.0
63.219469564,310.0
63.271990691,270.0
63.324511819,287.0
63.377032946,315.0
63.429554073,333.0
63.482075200,311.0
63.534596328,349.0
63.587117455,390.0
63.639638582,392.0
63.692159709,467.0
63.744680837,471.0
63.797201964,513.0
63.849723091,650.0
63.902244218,706.0
63.954765346,774.0
64.007286473,851.0
64.059807600,843.0
64.112328727,939.0
64.164849855,851.0
64.217370982,802.0
64.269892109,742.0
64.322413237,622.0
64.374934364,599.0
64.427455491,510.0
64.479976618,510.0
64.532497746,425.0
64.585018873,432.0
64.637540000,402.0
64.690061127,419.0
64.742582255,409.0
64.795103382,363.0
64.847624509,383.0
64.900145636,416.0
64.952666764,454.0
65.005187891,434.0
65.057709018,478.0
65.110230145,487.0
65.162751273,493.0
65.215272400,466.0
65.267793527,433.0
65.320314654,424.0
65.372835782,364.0
65.425356909,375.0
65.477878036,347.0
65.530399164,316.0
65.582920291,336.0
65.635441418,350.0
65.687962545,279.0
65.740483673,302.0
65.793004800,326.0
65.845525927,358.0
65.898047054,323.0
65.950568182,338.0
66.003089309,338.0
66.055610436,353.0
66.108131563,327.0
66.160652691,348.0
66.213173818,343.0
66.265694945,306.0
66.318216072,290.0
66.370737200,285.0
66.423258327,284.0
66.475779454,250.0
66.528300581,265.0
66.580821709,320.0
66.633342836,283.0
66.685863963,233.0
66.738385090,266.0
66.790906218,279.0
66.843427345,252.0
66.895948472,246.0
66.948469600,263.0
67.000990727,260.0
67.053511854,270.0
67.106032981,239.0
67.158554109,235.0
67.211075236,251.0
67.263596363,250.0
67.316117490,236.0
67.368638618,276.0
67.421159745,261.0
67.473680872,207.0
67.526201999,272.0
67.578723127,276.0
67.631244254,231.0
67.683765381,249.0
67.736286508,234.0
67.788807636,246.0
67.841328763,220.0
67.893849890,229.0
67.946371017,258.0
67.998892145,278.0
68.051413272,258.0
68.103934399,249.0
68.156455527,238.0
68.208976654,263.0
68.261497781,250.0
68.314018908,228.0
68.366540036,262.0
68.419061163,226.0
68.471582290,238.0
68.524103417,265.0
68.576624545,246.0
68.629145672,236.0
68.681666799,264.0
68.734187926,245.0
68.786709054,238.0
68.839230181,253.0
68.891751308,274.0
68.944272435,250.0
68.996793563,275.0
69.049314690,281.0
69.101835817,311.0
69.154356944,287.0
69.206878072,280.0
69.259399199,346.0
69.311920326,359.0
69.364441453,395.0
69.416962581,440.0
69.469483708,503.0
69.522004835,546.0
69.574525963,563.0
69.627047090,672.0
69.679568217,762.0
69.732089344,805.0
69.784610472,764.0
69.837131599,732.0
69.889652726,614.0
69.942173853,618.0
69.994694981,599.0
70.047216108,494.0
70.099737235,470.0
70.152258362,416.0
70.204779490,401.0
70.257300617,311.0
70.309821744,316.0
70.362342871,275.0
70.414863999,342.0
70.467385126,312.0
70.519906253,344.0
70.572427380,347.0
70.624948508,332.0
70.677469635,311.0
70.729990762,379.0
70.782511890,370.0
70.835033017,387.0
70.887554144,367.0
70.940075271,384.0
70.992596399,429.0
71.045117526,439.0
71.097638653,437.0
71.150159780,409.0
71.202680908,366.0
71.255202035,343.0
71.307723162,331.0
71.360244289,321.0
71.412765417,280.0
71.465286544,276.0
71.517807671,266.0
71.570328798,286.0
71.622849926,308.0
71.675371053,269.0
71.727892180,251.0
71.780413307,257.0
71.832934435,280.0
71.885455562,274.0
71.937976689,269.0
71.990497816,252.0
72.043018944,248.0
72.095540071,246.0
72.148061198,228.0
72.200582326,230.0
72.253103453,252.0
72.305624580,254.0
72.358145707,241.0
72.410666835,239.0
72.463187962,249.0
72.515709089,254.0
72.568230216,249.0
72.620751344,247.0
72.673272471,283.0
72.725793598,272.0
72.778314725,277.0
72.830835853,337.0
72.883356980,315.0
72.935878107,239.0
72.988399234,320.0
73.040920362,328.0
73.093441489,336.0
73.145962616,305.0
73.198483743,294.0
73.251004871,293.0
73.303525998,269.0
73.356047125,244.0
73.408568253,274.0
73.461089380,245.0
73.513610507,239.0
73.566131634,282.0
73.618652762,249.0
73.671173889,225.0
73.723695016,235.0
73.776216143,234.0
73.828737271,227.0
73.881258398,233.0
73.933779525,248.0
73.986300652,237.0
74.038821780,211.0
74.091342907,229.0
74.143864034,192.0
74.196385161,201.0
74.248906289,252.0
74.301427416,203.0
74.353948543,227.0
74.406469670,217.0
74.458990798,235.0
74.511511925,221.0
74.564033052,244.0
74.616554179,225.0
74.669075307,180.0
74.721596434,200.0
74.774117561,220.0
74.826638689,212.0
74.879159816,249.0
74.931680943,229.0
74.984202070,216.0
75.036723198,244.0
75.089244325,241.0
75.141765452,240.0
75.194286579,256.0
75.246807707,277.0
75.299328834,289.0
75.351849961,284.0
75.404371088,292.0
75.456892216,275.0
75.509413343,325.0
75.561934470,339.0
75.614455597,388.0
75.666976725,488.0
75.719497852,411.0
75.772018979,490.0
75.824540106,481.0
75.877061234,509.0
75.929582361,507.0
75.982103488,506.0
76.034624616,454.0
76.087145743,542.0
76.139666870,494.0
76.192187997,497.0
76.244709125,539.0
76.297230252,501.0
76.349751379,548.0
76.402272506,566.0
76.454793634,513.0
76.507314761,485.0
76.559835888,482.0
76.612357015,500.0
76.664878143,434.0
76.717399270,458.0
76.769920397,477.0
76.822441524,442.0
76.874962652,453.0
76.927483779,477.0
76.980004906,471.0
77.032526033,475.0
77.085047161,548.0
77.137568288,603.0
77.190089415,651.0
77.242610542,679.0
77.295131670,735.0
77.347652797,771.0
77.400173924,763.0
77.452695052,803.0
77.505216179,855.0
77.557737306,889.0
77.610258433,859.0
77.662779561,840.0
77.715300688,783.0
77.767821815,764.0
77.820342942,670.0
77.872864070,667.0
77.925385197,617.0
77.977906324,588.0
78.030427451,470.0
78.082948579,472.0
78.135469706,440.0
78.187990833,421.0
78.240511960,446.0
78.293033088,395.0
78.345554215,378.0
78.398075342,404.0
78.450596469,364.0
78.503117597,354.0
78.555638724,366.0
78.608159851,359.0
78.660680979,373.0
78.713202106,390.0
78.765723233,350.0
78.818244360,348.0
78.870765488,362.0
78.923286615,327.0
78.975807742,313.0
79.028328869,313.0
79.080849997,272.0
79.133371124,280.0
79.185892251,278.0
79.238413378,281.0
79.290934506,261.0
79.343455633,219.0
79.395976760,249.0
79.448497887,285.0
79.501019015,242.0
79.553540142,270.0
79.606061269,212.0
79.658582396,234.0
79.711103524,227.0
79.763624651,190.0
79.816145778,228.0
79.868666905,238.0
79.921188033,261.0
79.973709160,251.0